Collecting GDAL==3.1.0
remote:          Downloading GDAL-3.1.0.tar.gz (592 kB)
remote:            ERROR: Command errored out with exit status 1:
remote:             command: /app/.heroku/python/bin/python -c 'import sys, setuptools, tokenize; sys.argv[0] = '"'"'/tmp/pip-install-8amiccka/GDAL/setup.py'"'"'; __file__='"'"'/tmp/pip-install-8amiccka/GDAL/setup.py'"'"';f=getattr(tokenize, '"'"'open'"'"', open)(__file__);code=f.read().replace('"'"'\r\n'"'"', '"'"'\n'"'"');f.close();exec(compile(code, __file__, '"'"'exec'"'"'))' egg_info --egg-base /tmp/pip-install-8amiccka/GDAL/pip-egg-info
remote:                 cwd: /tmp/pip-install-8amiccka/GDAL/
remote:            Complete output (121 lines):
remote:            WARNING: numpy not available!  Array support will not be enabled
remote:            /app/.heroku/python/lib/python3.7/distutils/dist.py:274: UserWarning: Unknown distribution option: 'long_description_content_type'
remote:              warnings.warn(msg)
remote:            running egg_info
remote:            creating /tmp/pip-install-8amiccka/GDAL/pip-egg-info/GDAL.egg-info
remote:            writing /tmp/pip-install-8amiccka/GDAL/pip-egg-info/GDAL.egg-info/PKG-INFO
remote:            writing dependency_links to /tmp/pip-install-8amiccka/GDAL/pip-egg-info/GDAL.egg-info/dependency_links.tx
remote:            writing requirements to /tmp/pip-install-8amiccka/GDAL/pip-egg-info/GDAL.egg-info/requires.txt
remote:            writing top-level names to /tmp/pip-install-8amiccka/GDAL/pip-egg-info/GDAL.egg-info/top_level.txt
remote:            writing manifest file '/tmp/pip-install-8amiccka/GDAL/pip-egg-info/GDAL.egg-info/SOURCES.txt'
remote:            Traceback (most recent call last):
remote:              File "/tmp/pip-install-8amiccka/GDAL/setup.py", line 151, in fetch_config
remote:                p = subprocess.Popen([command, args], stdout=subprocess.PIPE)
remote:              File "/app/.heroku/python/lib/python3.7/subprocess.py", line 800, in __init__
remote:                restore_signals, start_new_session)
remote:              File "/app/.heroku/python/lib/python3.7/subprocess.py", line 1551, in _execute_child
remote:                raise child_exception_type(errno_num, err_msg, err_filename)
remote:            FileNotFoundError: [Errno 2] No such file or directory: '../../apps/gdal-config': '../../apps/gdal-config
remote:            
remote:            During handling of the above exception, another exception occurred:
remote:            
remote:            Traceback (most recent call last):
remote:              File "/tmp/pip-install-8amiccka/GDAL/setup.py", line 250, in get_gdal_config
remote:                return fetch_config(option, gdal_config=self.gdal_config)
remote:              File "/tmp/pip-install-8amiccka/GDAL/setup.py", line 154, in fetch_config
remote:                raise gdal_config_error(e)
remote:            __main__.gdal_config_error: [Errno 2] No such file or directory: '../../apps/gdal-config': '../../apps/gdal-config'
remote:            
remote:            During handling of the above exception, another exception occurred:
remote:            
remote:            Traceback (most recent call last):
remote:              File "/tmp/pip-install-8amiccka/GDAL/setup.py", line 151, in fetch_config
remote:                p = subprocess.Popen([command, args], stdout=subprocess.PIPE)
remote:              File "/app/.heroku/python/lib/python3.7/subprocess.py", line 800, in __init__
remote:                restore_signals, start_new_session)
remote:              File "/app/.heroku/python/lib/python3.7/subprocess.py", line 1551, in _execute_child
remote:                raise child_exception_type(errno_num, err_msg, err_filename)
remote:            FileNotFoundError: [Errno 2] No such file or directory: 'gdal-config': 'gdal-config'
remote:            
remote:            During handling of the above exception, another exception occurred:
remote:            
remote:            Traceback (most recent call last):
remote:              File "/tmp/pip-install-8amiccka/GDAL/setup.py", line 257, in get_gdal_config
remote:                return fetch_config(option)
remote:              File "/tmp/pip-install-8amiccka/GDAL/setup.py", line 154, in fetch_config
remote:                raise gdal_config_error(e)
remote:            __main__.gdal_config_error: [Errno 2] No such file or directory: 'gdal-config': 'gdal-config'
remote:            
remote:            During handling of the above exception, another exception occurred:
remote:            
remote:            Traceback (most recent call last):
remote:              File "<string>", line 1, in <module>
remote:              File "/tmp/pip-install-8amiccka/GDAL/setup.py", line 477, in <module>
remote:                setup(**setup_kwargs)
remote:              File "/app/.heroku/python/lib/python3.7/site-packages/setuptools/__init__.py", line 129, in setup
remote:                return distutils.core.setup(**attrs)
remote:              File "/app/.heroku/python/lib/python3.7/distutils/core.py", line 148, in setup
remote:                dist.run_commands()
remote:              File "/app/.heroku/python/lib/python3.7/distutils/dist.py", line 966, in run_commands
remote:                self.run_command(cmd)
remote:              File "/app/.heroku/python/lib/python3.7/distutils/dist.py", line 985, in run_command
remote:                cmd_obj.run()
remote:              File "/app/.heroku/python/lib/python3.7/site-packages/setuptools/command/egg_info.py", line 278, in run
remote:                self.find_sources()
remote:              File "/app/.heroku/python/lib/python3.7/site-packages/setuptools/command/egg_info.py", line 293, in find_sources
remote:                mm.run()
remote:              File "/app/.heroku/python/lib/python3.7/site-packages/setuptools/command/egg_info.py", line 524, in run
remote:                self.add_defaults()
remote:              File "/app/.heroku/python/lib/python3.7/site-packages/setuptools/command/egg_info.py", line 560, in add_defaults
remote:                sdist.add_defaults(self)
remote:              File "/app/.heroku/python/lib/python3.7/distutils/command/sdist.py", line 228, in add_defaults
remote:                self._add_defaults_ext()
remote:              File "/app/.heroku/python/lib/python3.7/distutils/command/sdist.py", line 311, in _add_defaults_ext
remote:                build_ext = self.get_finalized_command('build_ext')
remote:              File "/app/.heroku/python/lib/python3.7/distutils/cmd.py", line 299, in get_finalized_command
remote:                cmd_obj.ensure_finalized()
remote:              File "/app/.heroku/python/lib/python3.7/distutils/cmd.py", line 107, in ensure_finalized
remote:                self.finalize_options()
remote:              File "/tmp/pip-install-8amiccka/GDAL/setup.py", line 320, in finalize_options
remote:                self.gdaldir = self.get_gdal_config('prefix')
remote:              File "/tmp/pip-install-8amiccka/GDAL/setup.py", line 263, in get_gdal_config
remote:                raise gdal_config_error(traceback_string + '\n' + msg)
remote:            __main__.gdal_config_error: Traceback (most recent call last):
remote:              File "/tmp/pip-install-8amiccka/GDAL/setup.py", line 151, in fetch_config
remote:                p = subprocess.Popen([command, args], stdout=subprocess.PIPE)
remote:              File "/app/.heroku/python/lib/python3.7/subprocess.py", line 800, in __init__
remote:                restore_signals, start_new_session)
remote:              File "/app/.heroku/python/lib/python3.7/subprocess.py", line 1551, in _execute_child
remote:                raise child_exception_type(errno_num, err_msg, err_filename)
remote:            FileNotFoundError: [Errno 2] No such file or directory: '../../apps/gdal-config': '../../apps/gdal-config
remote:            
remote:            During handling of the above exception, another exception occurred:
remote:            
remote:            Traceback (most recent call last):
remote:              File "/tmp/pip-install-8amiccka/GDAL/setup.py", line 250, in get_gdal_config
remote:                return fetch_config(option, gdal_config=self.gdal_config)
remote:              File "/tmp/pip-install-8amiccka/GDAL/setup.py", line 154, in fetch_config
remote:                raise gdal_config_error(e)
remote:            gdal_config_error: [Errno 2] No such file or directory: '../../apps/gdal-config': '../../apps/gdal-config
remote:            
remote:            During handling of the above exception, another exception occurred:
remote:            
remote:            Traceback (most recent call last):
remote:              File "/tmp/pip-install-8amiccka/GDAL/setup.py", line 151, in fetch_config
remote:                p = subprocess.Popen([command, args], stdout=subprocess.PIPE)
remote:              File "/app/.heroku/python/lib/python3.7/subprocess.py", line 800, in __init__
remote:                restore_signals, start_new_session)
remote:              File "/app/.heroku/python/lib/python3.7/subprocess.py", line 1551, in _execute_child
remote:                raise child_exception_type(errno_num, err_msg, err_filename)
remote:            FileNotFoundError: [Errno 2] No such file or directory: 'gdal-config': 'gdal-config'
remote:            
remote:            During handling of the above exception, another exception occurred:
remote:            
remote:            Traceback (most recent call last):
remote:              File "/tmp/pip-install-8amiccka/GDAL/setup.py", line 257, in get_gdal_config
remote:                return fetch_config(option)
remote:              File "/tmp/pip-install-8amiccka/GDAL/setup.py", line 154, in fetch_config
remote:                raise gdal_config_error(e)
remote:            gdal_config_error: [Errno 2] No such file or directory: 'gdal-config': 'gdal-config'
remote:            
remote:            Could not find gdal-config. Make sure you have installed the GDAL native library and development headers.
remote:            ----------------------------------------
remote:        ERROR: Command errored out with exit status 1: python setup.py egg_info Check the logs for full command output.
remote: The command '/bin/sh -c STACK=heroku-18 /tmp/buildpack/python/bin/compile /app /tmp/build_cache /tmp/env' returned a non-zero code: 1
remote: 
remote: Verifying deploy...
remote: 
remote: !       Push rejected to classifymangroves.
remote: 
To https://git.heroku.com/classifymangroves.git
 ! [remote rejected] master -> master (pre-receive hook declined)
error: failed to push some refs to 'https://git.heroku.com/classifymangroves.git'